2023-01-29 18:21:21,606 INFO server Auth successful
2023-01-29 18:21:21,610 ERROR server Exception on /api/run_experiment [POST]
Traceback (most recent call last):
  File "/home/saurabh/miniconda3/envs/tf2/lib/python3.9/site-packages/flask/app.py", line 2525, in wsgi_app
    response = self.full_dispatch_request()
  File "/home/saurabh/miniconda3/envs/tf2/lib/python3.9/site-packages/flask/app.py", line 1822, in full_dispatch_request
    rv = self.handle_user_exception(e)
  File "/home/saurabh/miniconda3/envs/tf2/lib/python3.9/site-packages/flask/app.py", line 1820, in full_dispatch_request
    rv = self.dispatch_request()
  File "/home/saurabh/miniconda3/envs/tf2/lib/python3.9/site-packages/flask/app.py", line 1796, in dispatch_request
    return self.ensure_sync(self.view_functions[rule.endpoint])(**view_args)
  File "/home/saurabh/miniconda3/envs/tf2/lib/python3.9/site-packages/flask_httpauth.py", line 172, in decorated
    return self.ensure_sync(f)(*args, **kwargs)
  File "/home/saurabh/code-energy-consumption/server/server.py", line 157, in run_function_and_return_result
    output = run_function(
  File "/home/saurabh/code-energy-consumption/server/server.py", line 107, in run_function
    exec(imports)
  File "<string>", line 1, in <module>
  File "/home/saurabh/miniconda3/envs/tf2/lib/python3.9/site-packages/tensorflow/__init__.py", line 51, in <module>
    from ._api.v2 import compat
  File "/home/saurabh/miniconda3/envs/tf2/lib/python3.9/site-packages/tensorflow/_api/v2/compat/__init__.py", line 37, in <module>
    from . import v1
  File "/home/saurabh/miniconda3/envs/tf2/lib/python3.9/site-packages/tensorflow/_api/v2/compat/v1/__init__.py", line 30, in <module>
    from . import compat
  File "/home/saurabh/miniconda3/envs/tf2/lib/python3.9/site-packages/tensorflow/_api/v2/compat/v1/compat/__init__.py", line 38, in <module>
    from . import v2
  File "/home/saurabh/miniconda3/envs/tf2/lib/python3.9/site-packages/tensorflow/_api/v2/compat/v1/compat/v2/__init__.py", line 28, in <module>
    from tensorflow._api.v2.compat.v2 import __internal__
  File "/home/saurabh/miniconda3/envs/tf2/lib/python3.9/site-packages/tensorflow/_api/v2/compat/v2/__init__.py", line 33, in <module>
    from . import compat
  File "/home/saurabh/miniconda3/envs/tf2/lib/python3.9/site-packages/tensorflow/_api/v2/compat/v2/compat/__init__.py", line 38, in <module>
    from . import v2
  File "/home/saurabh/miniconda3/envs/tf2/lib/python3.9/site-packages/tensorflow/_api/v2/compat/v2/compat/v2/__init__.py", line 37, in <module>
    from tensorflow._api.v2.compat.v2 import distribute
  File "/home/saurabh/miniconda3/envs/tf2/lib/python3.9/site-packages/tensorflow/_api/v2/compat/v2/distribute/__init__.py", line 182, in <module>
    from . import experimental
  File "/home/saurabh/miniconda3/envs/tf2/lib/python3.9/site-packages/tensorflow/_api/v2/compat/v2/distribute/experimental/__init__.py", line 10, in <module>
    from . import rpc
  File "/home/saurabh/miniconda3/envs/tf2/lib/python3.9/site-packages/tensorflow/_api/v2/compat/v2/distribute/experimental/rpc/__init__.py", line 8, in <module>
    from tensorflow.python.distribute.experimental.rpc.rpc_ops import Client
  File "/home/saurabh/miniconda3/envs/tf2/lib/python3.9/site-packages/tensorflow/python/distribute/experimental/__init__.py", line 22, in <module>
    from tensorflow.python.distribute.failure_handling import failure_handling
  File "/home/saurabh/miniconda3/envs/tf2/lib/python3.9/site-packages/tensorflow/python/distribute/failure_handling/failure_handling.py", line 34, in <module>
    from tensorflow.python.distribute.failure_handling import gce_util
  File "/home/saurabh/miniconda3/envs/tf2/lib/python3.9/site-packages/tensorflow/python/distribute/failure_handling/gce_util.py", line 20, in <module>
    import requests
  File "/home/saurabh/miniconda3/envs/tf2/lib/python3.9/site-packages/requests/__init__.py", line 48, in <module>
    from charset_normalizer import __version__ as charset_normalizer_version
  File "/home/saurabh/miniconda3/envs/tf2/lib/python3.9/site-packages/charset_normalizer/__init__.py", line 23, in <module>
    from charset_normalizer.api import from_fp, from_path, from_bytes, normalize
  File "/home/saurabh/miniconda3/envs/tf2/lib/python3.9/site-packages/charset_normalizer/api.py", line 10, in <module>
    from charset_normalizer.md import mess_ratio
AttributeError: partially initialized module 'charset_normalizer' has no attribute 'md__mypyc' (most likely due to a circular import)
2023-01-29 18:21:21,611 INFO werkzeug 127.0.0.1 - - [29/Jan/2023 18:21:21] "[35m[1mPOST /api/run_experiment HTTP/1.1[0m" 500 -
